# Generated by Django 2.1.5 on 2019-01-06 15:07

import django.contrib.auth.validators
from django.db import migrations, models


class Migration(migrations.Migration):

    dependencies = [
        ('backend', '0006_auto_20190106_1403'),
    ]

    operations = [
        migrations.AlterModelOptions(
            name='user',
            options={},
        ),
        migrations.RenameField(
            model_name='user',
            old_name='date_registered',
            new_name='date_joined',
        ),
        migrations.AlterField(
            model_name='user',
            name='bio',
            field=models.CharField(blank=True, default='', max_length=50),
        ),
        migrations.AlterField(
            model_name='user',
            name='first_name',
            field=models.CharField(default='', max_length=25),
        ),
        migrations.AlterField(
            model_name='user',
            name='id',
            field=models.AutoField(max_length=20, primary_key=True, serialize=False),
        ),
        migrations.AlterField(
            model_name='user',
            name='job_title',
            field=models.CharField(blank=True, default='', max_length=50),
        ),
        migrations.AlterField(
            model_name='user',
            name='last_name',
            field=models.CharField(default='', max_length=25),
        ),
        migrations.AlterField(
            model_name='user',
            name='middle_name',
            field=models.CharField(blank=True, default='', max_length=25),
        ),
        migrations.AlterField(
            model_name='user',
            name='username',
            field=models.CharField(error_messages={'unique': 'A user with that username already exists.'}, max_length=15, unique=True, validators=[django.contrib.auth.validators.UnicodeUsernameValidator()]),
        ),
    ]
